<mujocoinclude>

    <!-- E05 机械臂与 Robotiq 2f-85 夹爪 运动链 -->
    <body name="base_link" pos="0.75 0.75 0.4"> <!-- 调整机器人底座的位置 -->
        <geom type="mesh" contype="0" conaffinity="0" group="1" rgba="0.501961 0.501961 0.501961 1" mesh="base_link" />
        <geom type="mesh" rgba="0.501961 0.501961 0.501961 1" mesh="base_link" />
    </body>
    <body name="link1" pos="0.75 0.75 0.4735" quat="0.707107 0 0 0.707107" >
        <inertial pos="-0.0218175 -1.34618e-05 0.0953928" quat="0.696024 -0.147787 -0.14991 0.686467" mass="2.58559" diaginertia="0.0143616 0.0141793 0.00506835" />
        <!-- <joint name="joint1" pos="0 0 0" axis="0 0 1" limited="true" range="-3.14159 3.14159" damping='200' /> -->
        <joint name="joint1" pos="0 0 0" axis="0 0 1" armature="1.5708" limited="true" range="-3.14159 3.14159" damping='200' />
        <geom type="mesh" contype="0" conaffinity="0" group="1" rgba="0.772549 0.752941 0.733333 1" mesh="link1" />
        <geom type="mesh" rgba="0.772549 0.752941 0.733333 1" mesh="link1" />
        <body name="link2" pos="0 0 0.1465" quat="0.5 -0.5 -0.5 0.5">
            <inertial pos="4.42659e-06 -0.15814 0.130501" quat="0.491565 0.508215 -0.508335 0.491606" mass="1.21311" diaginertia="0.0159807 0.0154676 0.00149746" />
            <joint name="joint2" pos="0 0 0" axis="0 0 -1" limited="true" range="-3.14159 3.14159" damping='200' />
            <geom type="mesh" contype="0" conaffinity="0" group="1" rgba="0.792157 0.819608 0.933333 1" mesh="link2" />
            <geom type="mesh" rgba="0.792157 0.819608 0.933333 1" mesh="link2" />
            <body name="link3" pos="0 -0.38 0">
                <inertial pos="-0.0414786 1.14213e-05 0.0194164" quat="0.601987 0.371892 0.373044 0.600122" mass="1.53239" diaginertia="0.00608826 0.00587729 0.00215529" />
                <!-- <joint name="joint3" pos="0 0 0" axis="0 0 -1" limited="true" range="-3.14159 3.14159" damping='200' /> -->
                <joint name="joint3" pos="0 0 0" axis="0 0 -1" armature="1.5708" limited="true" range="-4.71238 1.5708" damping='200' />
                <geom type="mesh" contype="0" conaffinity="0" group="1" rgba="0.866667 0.866667 0.890196 1" mesh="link3" />
                <geom type="mesh" rgba="0.866667 0.866667 0.890196 1" mesh="link3" />
                <body name="link4" pos="0 0 0" quat="0.5 -0.5 0.5 -0.5">
                    <inertial pos="3.8238e-05 -0.0589656 -0.257081" quat="0.988248 -0.152858 -0.000415939 -0.000860755" mass="0.475189" diaginertia="0.00538322 0.0052745 0.000778119" />
                    <joint name="joint4" pos="0 0 0" axis="0 0 1" limited="true" range="-3.14159 3.14159" damping='100' />
                    <geom type="mesh" contype="0" conaffinity="0" group="1" rgba="0.772549 0.752941 0.733333 1" mesh="link4" />
                    <geom type="mesh" rgba="0.772549 0.752941 0.733333 1" mesh="link4" />
                    <body name="link5" pos="0 0 -0.42" quat="0.499998 -0.5 0.5 0.500002">
                        <inertial pos="1.42418e-06 0.0365906 -0.0159722" quat="0.527641 0.849468 0.000113207 -7.90953e-05" mass="0.811919" diaginertia="0.00229898 0.00217056 0.000742684" />
                        <!-- <joint name="joint5" pos="0 0 0" axis="0 0 1" limited="true" range="-3.14159 3.14159" damping='100' /> -->
                        <joint name="joint5" pos="0 0 0" axis="0 0 1" armature="1.5708" limited="true" range="-4.71238 1.5708" damping='100' />
                        <geom type="mesh" contype="0" conaffinity="0" group="1" rgba="0.792157 0.819608 0.933333 1" mesh="link5" />
                        <geom type="mesh" rgba="0.792157 0.819608 0.933333 1" mesh="link5" />
                        <body name="link6" pos="0 0.155 0" quat="0.707105 -0.707108 0 0">
                            <inertial pos="-4.84703e-06 0.00109667 -0.0032406" quat="0.999926 0.0120786 2.3554e-05 -0.00120144" mass="0.75038" diaginertia="0.00129697 0.00122959 0.00051245" />
                            <joint name="joint6" pos="0 0 0" axis="0 0 -1" limited="true" range="-3.14159 3.14159" armature="0.5" damping='100' />
                            <geom type="mesh" contype="0" conaffinity="0" group="1" rgba="0.776471 0.756863 0.737255 1" mesh="link6" />
                            <geom type="mesh" rgba="0.776471 0.756863 0.737255 1" mesh="link6" />
                            <geom size="0.01" contype="0" conaffinity="0" group="1" rgba="1 0 0 1" />
                            
                            <!-- 导入 Robotiq 2f-85 运动链 -->
                            <body name="robotiq_2f_85" pos="0 0 0" childclass="robotiq2f85">
                                <geom mesh="robotiq-2f-base" />
                                <geom class="robotiq_col" type="mesh" mesh="robotiq-2f-base" euler="0 0 0"/>
                                <body name="robotiq_2f_85_right_driver" pos="0 0.0306011 0.054904">
                                    <inertial pos="0 0.01575 0.05295" quat="0.738425 0.674335 0 0" mass="0.2" diaginertia="0.00043212 0.000431866 0.000360253" />
                                    <joint name="robotiq_2f_85_right_driver_joint" range="0 0.834" />
                                    <geom mesh="robotiq-2f-driver" />
                                    <geom pos="0 0.0315 -0.0041" mesh="robotiq-2f-coupler" />
                                    <geom class="robotiq_col" pos="0 0.0315 -0.0041" type="mesh" mesh="robotiq-2f-coupler" />
                                    <body name="robotiq_2f_85_right_follower" pos="0 0.0376 0.043">
                                        <inertial pos="0 0 0.055" quat="0.707107 0.707107 0 0" mass="0.2" diaginertia="0.000380833 0.000380833 0.00036" />
                                        <joint name="robotiq_2f_85_right_follower_joint" range="-2.96706 2.96706" />
                                        <geom mesh="robotiq-2f-follower" />
                                        <geom type="mesh" mesh="robotiq-2f-pad" rgba="1 1 1 1"/>
                                        <geom class="robotiq_pad_col" type="box" size=".01 .003 .0175" pos="0 -.021 .031"/>
                                        <geom class="robotiq_pad_col" type="capsule" size=".004 .008" pos="0 -.019 .045" axisangle="0.1 1 0 1.57"/>
                                        <geom class="robotiq_pad_col" type="capsule" size=".004 .008" pos="0 -.019 .036" axisangle="0.1 1 0 1.57"/>
                                        <geom class="robotiq_pad_col" type="capsule" size=".004 .008" pos="0 -.019 .028" axisangle="0.1 1 0 1.57"/>
                                        <geom class="robotiq_pad_col" type="capsule" size=".004 .008" pos="0 -.019 .019" axisangle="0.1 1 0 1.57"/>
                                        <geom class="robotiq_pad_col" type="capsule" size=".004 .008" pos="0 -.019 .045" axisangle="-.1 1 0 1.57"/>
                                        <geom class="robotiq_pad_col" type="capsule" size=".004 .008" pos="0 -.019 .036" axisangle="-.1 1 0 1.57"/>
                                        <geom class="robotiq_pad_col" type="capsule" size=".004 .008" pos="0 -.019 .028" axisangle="-.1 1 0 1.57"/>
                                        <geom class="robotiq_pad_col" type="capsule" size=".004 .008" pos="0 -.019 .019" axisangle="-.1 1 0 1.57"/>
                                    </body>
                                </body>
                                <body name="robotiq_2f_85_right_spring_link" pos="0 0.012 0.0614">
                                    <inertial pos="0 0 0.055" quat="0.707107 0.707107 0 0" mass="0.1" diaginertia="0.000190833 0.000190833 0.00018" />
                                    <joint name="robotiq_2f_85_right_spring_link_joint" range="-2.96706 2.96706" />
                                    <geom mesh="robotiq-2f-spring_link"/>
                                    <geom class="robotiq_col" type="box" size=".0125 .007 .014" pos="0 .032 .0365" euler="-.7 0 0"/>
                                    <geom class="robotiq_col" type="box" size=".0180 .007 .022" pos="0 .012 0.013" euler="-.7 0 0"/>
                                    <site name="gripper_right" type="sphere" size="0.01" pos="0 0.037 0.043" rgba="1 0 0 1" group="3"/>
                                </body>
                                <body name="robotiq_2f_85_left_driver" pos="0 -0.0306011 0.054904" quat="0 0 0 1">
                                    <inertial pos="0 0.01575 0.05295" quat="0.738425 0.674335 0 0" mass="0.2" diaginertia="0.00043212 0.000431866 0.000360253" />
                                    <joint name="robotiq_2f_85_left_driver_joint" range="0 0.834" />
                                    <geom mesh="robotiq-2f-driver" />
                                    <geom pos="0 0.0315 -0.0041" mesh="robotiq-2f-coupler" />
                                    <geom class="robotiq_col" pos="0 0.0315 -0.0041" type="mesh" mesh="robotiq-2f-coupler" />
                                    <body name="robotiq_2f_85_left_follower" pos="0 0.0376 0.043">
                                        <inertial pos="0 0 0.055" quat="0.707107 0.707107 0 0" mass="0.2" diaginertia="0.000380833 0.000380833 0.00036" />
                                        <joint name="robotiq_2f_85_left_follower_joint" range="-2.96706 2.96706" />
                                        <geom mesh="robotiq-2f-follower" />
                                        <geom type="mesh" mesh="robotiq-2f-pad" rgba="1 1 1 1"/>
                                        <geom class="robotiq_pad_col" type="box" size=".01 .003 .0175" pos="0 -.021 .031"/>
                                        <geom class="robotiq_pad_col" type="capsule" size=".004 .008" pos="0 -.019 .045" axisangle="0.1 1 0 1.57"/>
                                        <geom class="robotiq_pad_col" type="capsule" size=".004 .008" pos="0 -.019 .036" axisangle="0.1 1 0 1.57"/>
                                        <geom class="robotiq_pad_col" type="capsule" size=".004 .008" pos="0 -.019 .028" axisangle="0.1 1 0 1.57"/>
                                        <geom class="robotiq_pad_col" type="capsule" size=".004 .008" pos="0 -.019 .019" axisangle="0.1 1 0 1.57"/>
                                        <geom class="robotiq_pad_col" type="capsule" size=".004 .008" pos="0 -.019 .045" axisangle="-.1 1 0 1.57"/>
                                        <geom class="robotiq_pad_col" type="capsule" size=".004 .008" pos="0 -.019 .036" axisangle="-.1 1 0 1.57"/>
                                        <geom class="robotiq_pad_col" type="capsule" size=".004 .008" pos="0 -.019 .028" axisangle="-.1 1 0 1.57"/>
                                        <geom class="robotiq_pad_col" type="capsule" size=".004 .008" pos="0 -.019 .019" axisangle="-.1 1 0 1.57"/>
                                    </body>
                                </body>
                                <body name="robotiq_2f_85_left_spring_link" pos="0 -0.012 0.0614" quat="0 0 0 1">
                                    <inertial pos="0 0 0.055" quat="0.707107 0.707107 0 0" mass="0.1" diaginertia="0.000190833 0.000190833 0.00018" />
                                    <joint name="robotiq_2f_85_left_spring_link_joint" range="-2.96706 2.96706" />
                                    <geom mesh="robotiq-2f-spring_link"/>
                                    <geom class="robotiq_col" type="box" size=".0125 .007 .014" pos="0 .032 .0365" euler="-.7 0 0"/>
                                    <geom class="robotiq_col" type="box" size=".0180 .007 .022" pos="0 .012 0.013" euler="-.7 0 0"/>
                                    <site name="gripper_left" type="sphere" size="0.01" pos="0 0.037 0.043" rgba="1 0 0 1" group="3"/>
                                </body>
                            </body>
                            <body name="gripper_center_link" pos="0 0 0.14" quat="0 0 0 0">
                                <site name="gripper_center" pos="0 0 0" rgba="1 0 0 1" size="0.01 0.01 0.01"></site>
                            </body>
                            <!-- 夹爪导入结束 -->

                        </body>
                    </body>
                </body>
            </body>
        </body>
    </body>


</mujocoinclude>