<mujocoinclude>
    <body name="base_link" pos="0.75 0.75 0.4"> <!-- 调整机器人底座的位置 -->
        <geom type="mesh" contype="0" conaffinity="0" group="1" rgba="0.501961 0.501961 0.501961 1" mesh="base_link" />
        <geom type="mesh" rgba="0.501961 0.501961 0.501961 1" mesh="base_link" />
    </body>
    <body name="link1" pos="0.75 0.75 0.4735">
        <inertial pos="-0.0218175 -1.34618e-05 0.0953928" quat="0.696024 -0.147787 -0.14991 0.686467" mass="2.58559" diaginertia="0.0143616 0.0141793 0.00506835" />
        <!-- <joint name="joint1" pos="0 0 0" axis="0 0 1" limited="true" range="-3.14159 3.14159" damping='200' /> -->
        <joint name="joint1" pos="0 0 0" axis="0 0 1" armature="1.5708" limited="true" range="-3.14159 3.14159" damping='200' />
        <geom type="mesh" contype="0" conaffinity="0" group="1" rgba="0.772549 0.752941 0.733333 1" mesh="link1" />
        <geom type="mesh" rgba="0.772549 0.752941 0.733333 1" mesh="link1" />
        <body name="link2" pos="0 0 0.1465" quat="0.5 -0.5 -0.5 0.5">
            <inertial pos="4.42659e-06 -0.15814 0.130501" quat="0.491565 0.508215 -0.508335 0.491606" mass="1.21311" diaginertia="0.0159807 0.0154676 0.00149746" />
            <joint name="joint2" pos="0 0 0" axis="0 0 -1" limited="true" range="-3.14159 3.14159" damping='200' />
            <geom type="mesh" contype="0" conaffinity="0" group="1" rgba="0.792157 0.819608 0.933333 1" mesh="link2" />
            <geom type="mesh" rgba="0.792157 0.819608 0.933333 1" mesh="link2" />
            <body name="link3" pos="0 -0.38 0" quat="0.707107 0 0 0.707107">
                <inertial pos="-0.0414786 1.14213e-05 0.0194164" quat="0.601987 0.371892 0.373044 0.600122" mass="1.53239" diaginertia="0.00608826 0.00587729 0.00215529" />
                <!-- <joint name="joint3" pos="0 0 0" axis="0 0 -1" limited="true" range="-3.14159 3.14159" damping='200' /> -->
                <joint name="joint3" pos="0 0 0" axis="0 0 -1" armature="1.5708" limited="true" range="-3.14159 3.14159" damping='200' />
                <geom type="mesh" contype="0" conaffinity="0" group="1" rgba="0.866667 0.866667 0.890196 1" mesh="link3" />
                <geom type="mesh" rgba="0.866667 0.866667 0.890196 1" mesh="link3" />
                <body name="link4" pos="0 0 0" quat="0.5 -0.5 0.5 -0.5">
                    <inertial pos="3.8238e-05 -0.0589656 -0.257081" quat="0.988248 -0.152858 -0.000415939 -0.000860755" mass="0.475189" diaginertia="0.00538322 0.0052745 0.000778119" />
                    <joint name="joint4" pos="0 0 0" axis="0 0 1" limited="true" range="-3.14159 3.14159" damping='100' />
                    <geom type="mesh" contype="0" conaffinity="0" group="1" rgba="0.772549 0.752941 0.733333 1" mesh="link4" />
                    <geom type="mesh" rgba="0.772549 0.752941 0.733333 1" mesh="link4" />
                    <body name="link5" pos="0 0 -0.42" quat="0.707105 -0.707108 0 0">
                        <inertial pos="1.42418e-06 0.0365906 -0.0159722" quat="0.527641 0.849468 0.000113207 -7.90953e-05" mass="0.811919" diaginertia="0.00229898 0.00217056 0.000742684" />
                        <!-- <joint name="joint5" pos="0 0 0" axis="0 0 1" limited="true" range="-3.14159 3.14159" damping='100' /> -->
                        <joint name="joint5" pos="0 0 0" axis="0 0 1" armature="1.5708" limited="true" range="-3.14159 3.14159" damping='100' />
                        <geom type="mesh" contype="0" conaffinity="0" group="1" rgba="0.792157 0.819608 0.933333 1" mesh="link5" />
                        <geom type="mesh" rgba="0.792157 0.819608 0.933333 1" mesh="link5" />
                        <body name="link6" pos="0 0.155 0" quat="0.707105 -0.707108 0 0">
                            <inertial pos="-4.84703e-06 0.00109667 -0.0032406" quat="0.999926 0.0120786 2.3554e-05 -0.00120144" mass="0.75038" diaginertia="0.00129697 0.00122959 0.00051245" />
                            <joint name="joint6" pos="0 0 0" axis="0 0 -1" limited="true" range="-3.14159 3.14159" damping='100' />
                            <geom type="mesh" contype="0" conaffinity="0" group="1" rgba="0.776471 0.756863 0.737255 1" mesh="link6" />
                            <geom type="mesh" rgba="0.776471 0.756863 0.737255 1" mesh="link6" />
                            <geom size="0.01" contype="0" conaffinity="0" group="1" rgba="1 0 0 1" />
                            
                            <!-- 导入 Robotiq 2f-85 运动链 -->
                            <include file="robotiq-2f-85-chain.xml"/>

                        </body>
                    </body>
                </body>
            </body>
        </body>
    </body>
</mujocoinclude>